<mujoco model="particle_box">
  <option timestep="0.005" iterations="10" ls_iterations="10" integrator="implicitfast">
    <flag eulerdamp="disable"/>
  </option>
  <default>
    <joint type="hinge" axis="0 0 1" limited="true" range="-.4 .4" damping="0" />
    <motor gear=".1" ctrlrange="-1 1" ctrllimited="true" />
    <default class="translation">
      <position kp="20" kv="10" ctrlrange="-0.4 0.4"/>
    </default>
    <geom friction="0.9"/>
  </default>

  <worldbody>
    <site name="reference" pos="0 0 0.01" size="0.01" rgba="0 0 0 0.0"/>
    
    <!-- Goal for the particle -->
    <body name="goal" mocap="true" pos="-0.05 0.0 0.01" quat="1 0 0 0">
      <geom type="sphere" size=".01" contype="0" conaffinity="0" rgba="0 1 0 .5" />
    </body>

    <!-- Safe area for the box -->
    <body name="safe_area" pos="0 0 0.005">
      <geom name="safe_area" type="box" size="0.15 0.15 0.001" rgba="0 1 0 0.2" contype="0" conaffinity="0"/>
    </body>

    <!-- The box that should stay in the safe area -->
    <body name="box" pos="0.0 0 0.02">
      <freejoint name="box_joint"/>
      <geom type="box" name="box" size="0.02 0.02 0.02" condim="3"
        friction="0.6" contype="2" conaffinity="1" solref="0.02 1" priority="1"
        mass="0.15"/>
        <site name="box_site" pos="0 0 0" size="0.01" />
    </body>

    <!-- The particle that needs to reach the goal -->
    <body name="pointmass" pos="-0.1 0.0 0.011">
      <joint name="root_x" type="slide" pos="0 0 0" axis="1 0 0" />
      <joint name="root_y" type="slide" pos="0 0 0" axis="0 1 0" />
      <geom name="pointmass" type="sphere" size=".01" mass=".3" />
      <site name="particle" pos="0 0 0" size="0.01" />
    </body>
  </worldbody>

  <actuator>
    <position name="x" site="particle" refsite="reference" gear="1 0 0 0 0 0" class="translation"/>
    <position name="y" site="particle" refsite="reference" gear="0 1 0 0 0 0" class="translation"/>
  </actuator>

  <sensor>
    <framepos name="box_position" objtype="site" objname="box_site"/>
  </sensor>
</mujoco>