<mujoco model="particle_corridor">
  <option timestep="0.005" iterations="10" ls_iterations="10" integrator="implicitfast">
    <flag eulerdamp="disable"/>
  </option>
  <default>
    <joint type="hinge" axis="0 0 1" limited="true" range="-.4 .4" damping="0" />
    <motor gear=".1" ctrlrange="-1 1" ctrllimited="true" />
    <default class="translation">
      <position kp="20" kv="10" ctrlrange="-0.4 0.4"/>
    </default>
    <geom friction="0.9"/>
  </default>

  <worldbody>
    <site name="reference" pos="0 0 0.01" size="0.01" rgba="0 0 0 0.0"/>
    
    <!-- Goal for the particle -->
    <body name="goal" mocap="true" pos="0.15 0.0 0.01" quat="1 0 0 0">
      <geom type="sphere" size=".01" contype="0" conaffinity="0" rgba="0 1 0 .5" />
    </body>

    <!-- Room walls with sites for touch sensors -->
    <!-- Left wall (with door opening) -->
    <body name="left_wall" pos="0.1 0.0 0.02">
      <geom name="left_wall_top" type="box" size="0.01 0.1 0.02" pos="0 0.15 0" rgba="0.7 0.7 0.7 1" 
        contype="1" conaffinity="1" solref="0.02 1"/>
      <geom name="left_wall_bottom" type="box" size="0.01 0.1 0.02" pos="0 -0.15 0" rgba="0.7 0.7 0.7 1" 
        contype="1" conaffinity="1" solref="0.02 1"/>
      <site name="left_wall_site_top" pos="0 0.15 0" size="0.01 0.1 0.02" type="box" rgba="0 0 1 0.3"/>
      <site name="left_wall_site_bottom" pos="0 -0.15 0" size="0.01 0.1 0.02" type="box" rgba="0 0 1 0.3"/>
    </body>
    
    <!-- Right wall -->
    <body name="right_wall" pos="-0.1 0.0 0.02">
      <geom name="right_wall_geom" type="box" size="0.01 0.25 0.02" rgba="0.7 0.7 0.7 1" 
        contype="1" conaffinity="1" solref="0.02 1"/>
      <site name="right_wall_site" pos="0 0 0" size="0.01 0.25 0.02" type="box" rgba="0 0 1 0.3"/>
    </body>
    
    <!-- Top wall -->
    <body name="top_wall" pos="0.0 0.25 0.02">
      <geom name="top_wall_geom" type="box" size="0.1 0.01 0.02" rgba="0.7 0.7 0.7 1" 
        contype="1" conaffinity="1" solref="0.02 1"/>
      <site name="top_wall_site" pos="0 0 0" size="0.1 0.01 0.02" type="box" rgba="0 0 1 0.3"/>
    </body>
    
    <!-- Bottom wall -->
    <body name="bottom_wall" pos="0.0 -0.25 0.02">
      <geom name="bottom_wall_geom" type="box" size="0.1 0.01 0.02" rgba="0.7 0.7 0.7 1" 
        contype="1" conaffinity="1" solref="0.02 1"/>
      <site name="bottom_wall_site" pos="0 0 0" size="0.1 0.01 0.02" type="box" rgba="0 0 1 0.3"/>
    </body>
    
    <!-- Door reference site -->
    <site name="door_center" pos="0.1 0 0.01" size="0.01" rgba="0 0 1 0.5"/>

    <!-- The box that should be pushed through the door -->
    <body name="box" pos="-0.05 0 0.02">
      <freejoint name="box_joint"/>
      <geom type="box" name="box" size="0.02 0.02 0.02" condim="3"
        friction="0.6" contype="2" conaffinity="1" solref="0.02 1" priority="1"
        mass="0.15" rgba="0.8 0.4 0.2 1"/>
      <site name="box_site" pos="0 0 0" size="0.01" />
    </body>

    <!-- The particle that pushes the box -->
    <body name="pointmass" pos="-0.05 0.05 0.011">
      <joint name="root_x" type="slide" pos="0 0 0" axis="1 0 0" />
      <joint name="root_y" type="slide" pos="0 0 0" axis="0 1 0" />
      <geom name="pointmass" type="sphere" size=".01" mass=".3" rgba="1 0 0 1"/>
      <site name="particle" pos="0 0 0" size="0.01" />
    </body>
  </worldbody>

  <actuator>
    <position name="x" site="particle" refsite="reference" gear="1 0 0 0 0 0" class="translation"/>
    <position name="y" site="particle" refsite="reference" gear="0 1 0 0 0 0" class="translation"/>
  </actuator>

  <sensor>
    <framepos name="box_position" objtype="site" objname="box_site"/>
    <!-- Touch sensors for wall collision detection -->
    <touch name="left_wall_touch_top" site="left_wall_site_top"/>
    <touch name="left_wall_touch_bottom" site="left_wall_site_bottom"/>
    <touch name="right_wall_touch" site="right_wall_site"/>
    <touch name="top_wall_touch" site="top_wall_site"/>
    <touch name="bottom_wall_touch" site="bottom_wall_site"/>
  </sensor>
</mujoco>